<?xml version="1.0" encoding="utf-8"?>
<!-- This URDF was automatically created by SolidWorks to URDF Exporter! Originally created by Stephen Brawner (brawner@gmail.com) 
     Commit Version: 1.6.0-4-g7f85cfe  Build Version: 1.6.7995.38578
     For more information, please see http://wiki.ros.org/sw_urdf_exporter -->
<robot
  name="URDF_v6.SLDASM">
  <link
    name="base">
    <inertial>
      <origin
        xyz="0.0944893864769673 -0.0347411727043226 -0.101278892046256"
        rpy="0 0 0" />
      <mass
        value="6.12695332790383" />
      <inertia
        ixx="0.0526628123209649"
        ixy="3.72389539763586E-05"
        ixz="9.46408382527756E-12"
        iyy="0.110440494279973"
        iyz="1.05397026658463E-11"
        izz="0.143434836820738" />
    </inertial>
    <visual>
      <origin
        xyz="0 0 0"
        rpy="0 0 0" />
      <geometry>
        <mesh
          filename="package://sysmap_package/meshes/base.STL" />
      </geometry>
      <material
        name="">
        <color
          rgba="0.501960784313725 0.501960784313725 1 1" />
      </material>
    </visual>
    <collision>
      <origin
        xyz="0 0 0"
        rpy="0 0 0" />
      <geometry>
        <mesh
          filename="package://sysmap_package/meshes/base.STL" />
      </geometry>
    </collision>
  </link>
  <link
    name="gliss_poteaux">
    <inertial>
      <origin
        xyz="0.118562971291442 0.0313919342087894 0.245093450706981"
        rpy="0 0 0" />
      <mass
        value="0.500902523414264" />
      <inertia
        ixx="0.00170021211145716"
        ixy="-1.77819170774254E-08"
        ixz="-2.61443758242469E-19"
        iyy="0.0036787944050683"
        iyz="-2.32246937822599E-06"
        izz="0.00242730566117116" />
    </inertial>
    <visual>
      <origin
        xyz="0 0 0"
        rpy="0 0 0" />
      <geometry>
        <mesh
          filename="package://sysmap_package/meshes/gliss_poteaux.STL" />
      </geometry>
      <material
        name="">
        <color
          rgba="0.792156862745098 0.819607843137255 0.933333333333333 1" />
      </material>
    </visual>
    <collision>
      <origin
        xyz="0 0 0"
        rpy="0 0 0" />
      <geometry>
        <mesh
          filename="package://sysmap_package/meshes/gliss_poteaux.STL" />
      </geometry>
    </collision>
  </link>
  <joint
    name="gliss_poteaux"
    type="prismatic">
    <origin
      xyz="0 0 0"
      rpy="0 0 0" />
    <parent
      link="base" />
    <child
      link="gliss_poteaux" />
    <axis
      xyz="0 0 -1" />
    <limit
      lower="0"
      upper="0"
      effort="0"
      velocity="0" />
  </joint>
  <link
    name="gliss_bras">
    <inertial>
      <origin
        xyz="0.557428474782956 -0.0205798453700184 -0.011047194653353"
        rpy="0 0 0" />
      <mass
        value="0.335167922240104" />
      <inertia
        ixx="0.000424219378364812"
        ixy="-5.1328730304103E-06"
        ixz="-1.9398128324772E-18"
        iyy="0.00273500591443091"
        iyz="-1.44140732216592E-07"
        izz="0.00289086824854067" />
    </inertial>
    <visual>
      <origin
        xyz="0 0 0"
        rpy="0 0 0" />
      <geometry>
        <mesh
          filename="package://sysmap_package/meshes/gliss_bras.STL" />
      </geometry>
      <material
        name="">
        <color
          rgba="1 1 0 1" />
      </material>
    </visual>
    <collision>
      <origin
        xyz="0 0 0"
        rpy="0 0 0" />
      <geometry>
        <mesh
          filename="package://sysmap_package/meshes/gliss_bras.STL" />
      </geometry>
    </collision>
  </link>
  <joint
    name="gliss_bras"
    type="prismatic">
    <origin
      xyz="0.29342493954964 0.0679999999953615 0.296721660586204"
      rpy="0 0 -3.14159265358979" />
    <parent
      link="gliss_poteaux" />
    <child
      link="gliss_bras" />
    <axis
      xyz="-1 0 0" />
    <limit
      lower="0"
      upper="0"
      effort="0"
      velocity="0" />
  </joint>
  <link
    name="verrin">
    <inertial>
      <origin
        xyz="-0.0125569937147453 0.00726734801902937 0.137936258865581"
        rpy="0 0 0" />
      <mass
        value="0.661789633465566" />
      <inertia
        ixx="0.00196990890859597"
        ixy="0.000207478841159757"
        ixz="-0.000153728211501711"
        iyy="0.00221074452321751"
        iyz="8.87559948806474E-05"
        izz="0.00114488105658826" />
    </inertial>
    <visual>
      <origin
        xyz="0 0 0"
        rpy="0 0 0" />
      <geometry>
        <mesh
          filename="package://sysmap_package/meshes/verrin.STL" />
      </geometry>
      <material
        name="">
        <color
          rgba="0.792156862745098 0.819607843137255 0.933333333333333 1" />
      </material>
    </visual>
    <collision>
      <origin
        xyz="0 0 0"
        rpy="0 0 0" />
      <geometry>
        <mesh
          filename="package://sysmap_package/meshes/verrin.STL" />
      </geometry>
    </collision>
  </link>
  <joint
    name="verrin"
    type="prismatic">
    <origin
      xyz="0.62905742609016 -0.0800000014712998 -0.029999999991313"
      rpy="3.14159265358979 0 0" />
    <parent
      link="gliss_bras" />
    <child
      link="verrin" />
    <axis
      xyz="0 0 1" />
    <limit
      lower="0"
      upper="0"
      effort="0"
      velocity="0" />
  </joint>
  <link
    name="rot_pince">
    <inertial>
      <origin
        xyz="0.000294022871902055 4.34457177786451E-05 0.0693101548820414"
        rpy="0 0 0" />
      <mass
        value="0.544998572652357" />
      <inertia
        ixx="0.000396325660254941"
        ixy="5.31600984171309E-07"
        ixz="2.45728709130073E-07"
        iyy="0.000397311801808361"
        iyz="-4.17603942090456E-07"
        izz="0.000638370220485151" />
    </inertial>
    <visual>
      <origin
        xyz="0 0 0"
        rpy="0 0 0" />
      <geometry>
        <mesh
          filename="package://sysmap_package/meshes/rot_pince.STL" />
      </geometry>
      <material
        name="">
        <color
          rgba="1 0.949019607843137 0.909803921568627 1" />
      </material>
    </visual>
    <collision>
      <origin
        xyz="0 0 0"
        rpy="0 0 0" />
      <geometry>
        <mesh
          filename="package://sysmap_package/meshes/rot_pince.STL" />
      </geometry>
    </collision>
  </link>
  <joint
    name="rot_pince"
    type="revolute">
    <origin
      xyz="-2.88675134771377E-05 4.99999999629686E-05 0.280984024501209"
      rpy="0 0 3.14159265358979" />
    <parent
      link="verrin" />
    <child
      link="rot_pince" />
    <axis
      xyz="0 0 1" />
    <limit
      lower="0"
      upper="0"
      effort="0"
      velocity="0" />
  </joint>
  <link
    name="gliss_boites">
    <inertial>
      <origin
        xyz="0 0 0"
        rpy="0 0 0" />
      <mass
        value="2.80592305978432" />
      <inertia
        ixx="0.00678202290107791"
        ixy="2.74320546351397E-18"
        ixz="-4.47642388658076E-18"
        iyy="0.0162652797341694"
        iyz="-0.000751021025269051"
        izz="0.0179647616711809" />
    </inertial>
    <visual>
      <origin
        xyz="0 0 0"
        rpy="0 0 0" />
      <geometry>
        <mesh
          filename="package://sysmap_package/meshes/gliss_boites.STL" />
      </geometry>
      <material
        name="">
        <color
          rgba="0.752941176470588 0.752941176470588 0.752941176470588 1" />
      </material>
    </visual>
    <collision>
      <origin
        xyz="0 0 0"
        rpy="0 0 0" />
      <geometry>
        <mesh
          filename="package://sysmap_package/meshes/gliss_boites.STL" />
      </geometry>
    </collision>
  </link>
  <joint
    name="gliss_boites"
    type="prismatic">
    <origin
      xyz="0.29242 0.244 -0.15901"
      rpy="0 0 -3.1416" />
    <parent
      link="base" />
    <child
      link="gliss_boites" />
    <axis
      xyz="-1 0 0" />
    <limit
      lower="0"
      upper="0.26"
      effort="0"
      velocity="0" />
  </joint>
</robot>